# Erros e Exceções

É muito comum encontrarmos erros ao escrevermos programas, o **Interpretador Python** é capaz de gerar **exceções** quando encontra erros, por exemplo uma **divisão por zero**. Um dos erros mais comuns de encontrarmos é o de síntaxe, quando não seguimos a estrutura correta da linguagem, chamamos esse erro de erro de síntaxe. Por exemplo:

```python
if 2 > 1 
	print("Dois maior do que um")

#   File "<stdin>", line 1
#   if 2 >1
#          ^
# SyntaxError: invalid syntax
```

Perceba, que de propósito, omitimos o **:** e o interpretador nos retorna um erro de **síntaxe inválida**

Além disso, erros também podem acontecer em **tempo de execução**, nesse caso eles são conhecidos como **exceções**. Eles ocorrem, por exemplo quando um arquivo que estamos tentando abrir não existe **(FileNotFoundError)**, dividir por zero **(ZeroDivisionError)**, módulos que tentamos importar e não são encontrados **(ImportError)** e uma série de outros. Quando esses erros em tempo de execução ocorrem, **Python** cria um objeto de exceção, e caso este não seja tratado de maneira própria, será impresso um **traceback** daquele erro e mais detalhes do motivo que ocorreu.

```python
x = 1/0

# Traceback (most recent call last):
#  File "<stdin>", line 1, in <module>
# ZeroDivisionError: division by zero

f = open("arquivo.txt") # Abrindo arquivo que não existe em nosso sistema de arquivos

# Traceback (most recent call last):
#  File "<stdin>", line 1, in <module>
# FileNotFoundError: [Errno 2] No such file or directory: 'arquivo.txt'
```

#### Exceções construídas no Python

Operações ilegais poderam gerar exceções, existem diversas exceções construídas em **Python** que são geradas quando erros correspondentes ocorrem, para vermos elas precisamos usar a função **locals()**

```python
e = locals()['__builtins__']
print(dir(e))
print(type(e))
```

Como podemos ver, essa função nos retornará um **<class 'module'>** com exceções construídas, funções e atributos. Algumas das exceções mais comuns são listadas a seguir:

| Exceção               | Causa                                                                                                                         |
|-----------------------|-------------------------------------------------------------------------------------------------------------------------------|
| AssertionError        | Surge quando o comando assert falha                                                                                           |
| AttributeError        | Surge quando uma atribuição ou referência falha                                                                               |
| EOFError              | Surge quando a função input() chega na condição de fim de arquivo                                                             |
| FloatingPointError    | Surge quando uma operação de ponto flutuante falha                                                                            |
| GeneratorExit         | Surge quando o método close() do gerador é chamado                                                                            |
| ImportError           | Surge quando o módulo importado não é encontrado                                                                              |
| IndexError            | Surge quando o índice de uma sequência está fora de alcance                                                                   |
| KeyError              | Surge quando uma chave não é encontrada no dicionário                                                                         |
| KeyboardInterrupt     | Surge quando um usuário aperta o botão de interrupção (CTRL + C ou delete)                                                    |
| MemoryError           | Surge quando acaba a memória de uma operação                                                                                  |
| NameError             | Surge quando uma variável não é encontrada no escopo local ou global                                                          |
| NotImplementedError   | Surge por métodos abstratos                                                                                                   |
| OSError               | Surge quando alguma operação de sistema causa algum erro de sistema                                                           |
| OverflowError         | Surge quando uma operação aritmética é muito grande para ser representada                                                     |
| ReferenceError        | Surge quando um proxy de referência fraco é usado para acessar um garbage collected referente                                 |
| RuntimeError          | Surge quando um erro não se encaixa em nenhuma outra categoria                                                                |
| StopIteration         | Surge pela função next() para indicar que não há mais itens para o iterador retornar                                          |
| SyntaxError           | Surge pelo parser quando um erro de síntaxe ocorre                                                                            |
| IndentationError      | Surge quando não indentamos nosso código                                                                                      |
| TabError              | Surge quando a indentação consiste de espaços e tabs impróprios                                                               |
| SystemError           | Surge quando o interpretador detecta um erro interno                                                                          |
| SystemExit            | Surge pela função sys.exit()                                                                                                  |
| TypeError             | Surge quando uma função ou operação é aplicada a um objeto de tipo incorreto                                                  |
| UnboundLocalError     | Surge quando uma referência é feita para uma variável local em uma função ou método, porém nenhum valor está preso à variável |
| UnicodeError          | Surge quando existe um erro relacionado a Unicode codificação ou decodificação                                                |
| UnicodeEncodeError    | Surge quando um erro de codificação de Unicode ocorre                                                                         |
| UnicodeDecodeError    | Surge quando um erro de decodificação de Unicode ocorre                                                                       |
| UnicodeTranslateError | Surge quando um erro de tradução de Unicode ocorre                                                                            |
| ValueError            | Surge quando uma função pega um argumento de tipo correto, porém de valor impróprio                                           |
| ZeroDivisionError     | Surge quando a segunda divisão ou módulo é zero                                                                               |

Além delas, podemos definir **nossas próprias exceções**, caso necessário, e para lidarmos com elas utilizamos as palavras-chave **try**, **except** e **finally**.

| Palavra-chave | Descrição                                                               |
|---------------|-------------------------------------------------------------------------|
| try           | nos permite testar um bloco de código por erros                         |
| except        | permite lidarmos com erros                                              |
| finally       | permite executarmos códigos independete do resultado do try e do except |

Por exemplo:

```python
try:
	print(x)
except:
	print("Uma exceção ocorreu")
```

O bloco **try** irá gerar uma exceção, uma vez que **x** não está definida, uma vez gerada, o bloco **except** é executado, caso não tivéssemos o bloco **try** o programa iria *crashar* e um erro surgiria. Podemos também definir diversos blocos de exceção.

```python
try:
	print(x)
except NameError:
	print("Variável x não está definida")
except:
	print("Algum outro erro ocorreu")
```

O bloco **finally**, se especificado, será executado independente de surgir ou não um erro no **try**

```python
try:
	print(x)
except:
	print("Algum erro ocorreu")
finally:
	print("O try e except foram finalizados")
```

Vimos que existem muitos erros e possibilidades deles ocorrerem em nosso programas, por isso é importante que tenhamos em mente a capacidade que **Python** nos traz de lidarmos com estes erros.







































































































